<mujoco model="Taks_T1">
  <compiler angle="radian" meshdir="meshes" />

  <default>
    <default class="torso_motor">
      <joint damping="0.05" armature="0.01" frictionloss="0.1"/>
    </default>
    <default class="leg_motor">
      <joint damping="0.05" armature="0.01" frictionloss="0.1"/>
    </default>
    <default class="ankle_motor">
      <joint damping="0.05" armature="0.01" frictionloss="0.1"/>
    </default>
    <default class="arm_motor">
      <joint damping="0.05" armature="0.01" frictionloss="0.1"/>
    </default>
    <default class="wrist_motor">
      <joint damping="0.05" armature="0.001" frictionloss="0.01"/>
    </default>
    <default class="neck_motor">
      <joint damping="0.02" armature="0.001" frictionloss="0.01"/>
    </default>
  </default>

  <asset>
    <mesh name="pelvis" file="pelvis.STL" />
    <mesh name="left_hip_pitch_link" file="left_hip_pitch_link.STL" />
    <mesh name="left_hip_roll_link" file="left_hip_roll_link.STL" />
    <mesh name="left_hip_yaw_link" file="left_hip_yaw_link.STL" />
    <mesh name="left_knee_link" file="left_knee_link.STL" />
    <mesh name="left_ankle_pitch_link" file="left_ankle_pitch_link.STL" />
    <mesh name="left_ankle_roll_link" file="left_ankle_roll_link.STL" />
    <mesh name="right_hip_pitch_link" file="right_hip_pitch_link.STL" />
    <mesh name="right_hip_roll_link" file="right_hip_roll_link.STL" />
    <mesh name="right_hip_yaw_link" file="right_hip_yaw_link.STL" />
    <mesh name="right_knee_link" file="right_knee_link.STL" />
    <mesh name="right_ankle_pitch_link" file="right_ankle_pitch_link.STL" />
    <mesh name="right_ankle_roll_link" file="right_ankle_roll_link.STL" />
    <mesh name="waist_yaw_link" file="waist_yaw_link.STL" />
    <mesh name="waist_roll_link" file="waist_roll_link.STL" />
    <mesh name="waist_pitch_link" file="waist_pitch_link.STL" />
    <mesh name="left_shoulder_pitch_link" file="left_shoulder_pitch_link.STL" />
    <mesh name="left_shoulder_roll_link" file="left_shoulder_roll_link.STL" />
    <mesh name="left_shoulder_yaw_link" file="left_shoulder_yaw_link.STL" />
    <mesh name="left_elbow_link" file="left_elbow_link.STL" />
    <mesh name="left_wrist_roll_link" file="left_wrist_roll_link.STL" />
    <mesh name="left_wrist_yaw_link" file="left_wrist_yaw_link.STL" />
    <mesh name="left_wrist_pitch_link" file="left_wrist_pitch_link.STL" />
    <mesh name="right_shoulder_pitch_link" file="right_shoulder_pitch_link.STL" />
    <mesh name="right_shoulder_roll_link" file="right_shoulder_roll_link.STL" />
    <mesh name="right_shoulder_yaw_link" file="right_shoulder_yaw_link.STL" />
    <mesh name="right_elbow_link" file="right_elbow_link.STL" />
    <mesh name="right_wrist_roll_link" file="right_wrist_roll_link.STL" />
    <mesh name="right_wrist_yaw_link" file="right_wrist_yaw_link.STL" />
    <mesh name="right_wrist_pitch_link" file="right_wrist_pitch_link.STL" />
    <mesh name="neck_yaw_link" file="neck_yaw_link.STL" />
    <mesh name="neck_roll_link" file="neck_roll_link.STL" />
    <mesh name="neck_pitch_link" file="neck_pitch_link.STL" />
  </asset>

  <worldbody>
    <body name="pelvis" pos="0 0 0.75">
      <site name="imu" size="0.01" pos="0.0 0.0 0.0" />
      <inertial pos="-0.000276 0.004540 -0.078485" quat="-0.483309 0.519158 0.510148 -0.486453" mass="3.34"
        diaginertia="0.00671618 0.0161253 0.0176076" />
      <freejoint name="pelvis"/>
      <geom type="mesh" contype="0" conaffinity="0" group="1" density="0" rgba="1.0 1.0 1.0 1"
        mesh="pelvis" />
      <geom type="mesh" rgba="1.0 1.0 1.0 1" mesh="pelvis" contype="2" conaffinity="1" />

      <body name="left_hip_pitch_link" pos="0.0 0.0919 -0.08747">
        <inertial pos="-0.019957 0.068375 -0.041781" quat="-0.588219 -0.416223 0.640256 0.266136" mass="0.91"
        diaginertia="0.000513325 0.00109885 0.00117005" />
        <joint name="left_hip_pitch_joint" pos="0 0 0" axis="0 1 0" range="-2.5307 2.8798"
          actuatorfrcrange="-120 120" class="leg_motor" />
        <geom type="mesh" contype="0" conaffinity="0" group="1" density="0" rgba="1.0 1.0 1.0 1"
          mesh="left_hip_pitch_link" />
        <geom type="mesh" rgba="1.0 1.0 1.0 1" mesh="left_hip_pitch_link" />
        <geom name="left_hip_collision" type="sphere" size="0.08" pos="0 0.04 -0.05" contype="0" conaffinity="0" rgba=".6 .2 .6 .2" group="3"/>

        <body name="left_hip_roll_link" pos="0.00795 0.0765 -0.04167" quat="0.996195 0 -0.0871557 0">
          <inertial pos="-0.007369 -0.000032 -0.073928" quat="0.617210 0.003424 0.786788 0.002045" mass="0.79"
        diaginertia="0.000472727 0.000626126 0.000641084" />
          <joint name="left_hip_roll_joint" pos="0 0 0" axis="1 0 0" range="-0.5236 2.9671"
            actuatorfrcrange="-97 97" class="leg_motor" />
          <geom type="mesh" contype="0" conaffinity="0" group="1" density="0" rgba="1.0 1.0 1.0 1"
            mesh="left_hip_roll_link" />
          <geom type="mesh" rgba="1.0 1.0 1.0 1" mesh="left_hip_roll_link" />

          <body name="left_hip_yaw_link" pos="0.00829 0.0 -0.1094">
            <inertial pos="-0.046231 0.023584 -0.159502" quat="0.577194 -0.562660 -0.408699 -0.428048" mass="1.822"
        diaginertia="0.00191107 0.00364049 0.00473262" />
            <joint name="left_hip_yaw_joint" pos="0 0 0" axis="0 0 1" range="-2.7576 2.7576"
              actuatorfrcrange="-97 97" class="leg_motor" />
            <geom type="mesh" contype="0" conaffinity="0" group="1" density="0" rgba="1.0 1.0 1.0 1"
              mesh="left_hip_yaw_link" />
            <geom type="mesh" rgba="1.0 1.0 1.0 1" mesh="left_hip_yaw_link" />

            <body name="left_knee_link" pos="-0.0484 0.0 -0.1665" quat="0.996195 0 0.0871557 0">
              <inertial pos="0.010920 -0.002203 -0.156771" quat="0.678951 -0.175857 0.688367 0.185070" mass="1.138"
        diaginertia="0.000686365 0.00368263 0.0037111" />
              <joint name="left_knee_joint" pos="0 0 0" axis="0 1 0" range="-0.087267 2.8798"
                actuatorfrcrange="-120 120" class="leg_motor" />
              <geom type="mesh" contype="0" conaffinity="0" group="1" density="0" rgba="1.0 1.0 1.0 1"
                mesh="left_knee_link" />
              <geom type="mesh" rgba="1.0 1.0 1.0 1" mesh="left_knee_link" />
              <geom name="left_shin_collision" type="capsule" size="0.05" fromto="0 0 -0.05 0 0 -0.25" contype="0" conaffinity="0" rgba=".2 .2 .6 .2" group="3"/>

              <body name="left_ankle_pitch_link" pos="0.0 0.0227 -0.2985">
                <inertial pos="0.000000 -0.024000 0.000000" quat="1.000000 -0.000070 -0.000000 -0.000005" mass="0.23"
        diaginertia="1.93535e-05 6.81815e-05 7.18285e-05" />
                <joint name="left_ankle_pitch_joint" pos="0 0 0" axis="0 1 0"
                  range="-0.87267 0.5236" actuatorfrcrange="-27 27" class="ankle_motor" />
                <geom type="mesh" contype="0" conaffinity="0" group="1" density="0" rgba="1.0 1.0 1.0 1"
                  mesh="left_ankle_pitch_link" />
                <geom type="mesh" rgba="1.0 1.0 1.0 1" mesh="left_ankle_pitch_link" />

                <body name="left_ankle_roll_link" pos="0.0 -0.024 0.0">
                  <inertial pos="0.039442 0.002884 -0.032059" quat="0.999149 0.009110 0.020904 -0.034363" mass="0.15"
        diaginertia="0.00012722 0.000547803 0.000633425" />
                  <joint name="left_ankle_roll_joint" pos="0 0 0" axis="1 0 0"
                    range="-0.2618 0.2618" actuatorfrcrange="-27 27" class="ankle_motor" />
                  <geom type="mesh" contype="0" conaffinity="0" group="1" density="0" rgba="1.0 1.0 1.0 1"
                    mesh="left_ankle_roll_link" />
                  <geom size="0.005" pos="-0.05 0.038 -0.046" rgba="1.0 1.0 1.0 1"/>
                  <geom size="0.005" pos="-0.05 -0.030 -0.046" rgba="1.0 1.0 1.0 1"/>
                  <geom size="0.005" pos="0.15 0.020 -0.046" rgba="1.0 1.0 1.0 1"/>
                  <geom size="0.005" pos="0.15 -0.034 -0.046" rgba="1.0 1.0 1.0 1"/>
                  <geom name="left_foot_collision" type="box" size="0.08 0.04 0.02" pos="0.05 0 -0.04" contype="0" conaffinity="0" rgba=".2 .2 .6 .2" group="3"/>
                </body>
              </body>
            </body>
          </body>
        </body>
      </body>

      <body name="right_hip_pitch_link" pos="0.0 -0.0913 -0.08747">
        <inertial pos="-0.019957 -0.068874 -0.041781" quat="0.416329 0.588113 0.266120 0.640292" mass="0.91"
        diaginertia="0.000513318 0.00109902 0.0011702" />
        <joint name="right_hip_pitch_joint" pos="0 0 0" axis="0 1 0" range="-2.5307 2.8798"
          actuatorfrcrange="-120 120" class="leg_motor" />
        <geom type="mesh" contype="0" conaffinity="0" group="1" density="0" rgba="1.0 1.0 1.0 1"
          mesh="right_hip_pitch_link" />
        <geom type="mesh" rgba="1.0 1.0 1.0 1" mesh="right_hip_pitch_link" />
        <geom name="right_hip_collision" type="sphere" size="0.08" pos="0 -0.04 -0.05" contype="0" conaffinity="0" rgba=".6 .2 .6 .2" group="3"/>

        <body name="right_hip_roll_link" pos="0.00795 -0.077 -0.04167" quat="0.996195 0 -0.0871557 0">
          <inertial pos="-0.007370 0.000033 -0.073928" quat="-0.003396 -0.617202 0.002105 0.786795" mass="0.79"
        diaginertia="0.000472728 0.000626098 0.000641055" />
          <joint name="right_hip_roll_joint" pos="0 0 0" axis="1 0 0" range="-2.9671 0.5236"
            actuatorfrcrange="-97 97" class="leg_motor" />
          <geom type="mesh" contype="0" conaffinity="0" group="1" density="0" rgba="1.0 1.0 1.0 1"
            mesh="right_hip_roll_link" />
          <geom type="mesh" rgba="1.0 1.0 1.0 1" mesh="right_hip_roll_link" />

          <body name="right_hip_yaw_link" pos="0.00829 0.0 -0.1094">
            <inertial pos="-0.046230 -0.023584 -0.159501" quat="-0.428050 -0.408699 -0.562659 0.577194" mass="1.822"
        diaginertia="0.00191107 0.00364058 0.0047327" />
            <joint name="right_hip_yaw_joint" pos="0 0 0" axis="0 0 1" range="-2.7576 2.7576"
              actuatorfrcrange="-97 97" class="leg_motor" />
            <geom type="mesh" contype="0" conaffinity="0" group="1" density="0" rgba="1.0 1.0 1.0 1"
              mesh="right_hip_yaw_link" />
            <geom type="mesh" rgba="1.0 1.0 1.0 1" mesh="right_hip_yaw_link" />

            <body name="right_knee_link" pos="-0.0484 -0.0005 -0.1665" quat="0.996195 0 0.0871557 0">
              <inertial pos="0.010319 0.003045 -0.153717" quat="0.437005 0.556898 -0.429215 0.560950" mass="1.138"
        diaginertia="0.000690132 0.00417376 0.00420862" />
              <joint name="right_knee_joint" pos="0 0 0" axis="0 1 0" range="-0.087267 2.8798"
                actuatorfrcrange="-120 120" class="leg_motor" />
              <geom type="mesh" contype="0" conaffinity="0" group="1" density="0" rgba="1.0 1.0 1.0 1"
                mesh="right_knee_link" />
              <geom type="mesh" rgba="1.0 1.0 1.0 1" mesh="right_knee_link" />
              <geom name="right_shin_collision" type="capsule" size="0.05" fromto="0 0 -0.05 0 0 -0.25" contype="0" conaffinity="0" rgba=".2 .2 .6 .2" group="3"/>

              <body name="right_ankle_pitch_link" pos="0.0 -0.0222 -0.2985">
                <inertial pos="0.000000 0.024000 0.000000" quat="1.000000 0.000071 0.000000 0.000004" mass="0.23"
        diaginertia="1.93534e-05 6.81821e-05 7.18293e-05" />
                <joint name="right_ankle_pitch_joint" pos="0 0 0" axis="0 1 0"
                  range="-0.87267 0.5236" actuatorfrcrange="-27 27" class="ankle_motor" />
                <geom type="mesh" contype="0" conaffinity="0" group="1" density="0" rgba="1.0 1.0 1.0 1"
                  mesh="right_ankle_pitch_link" />
                <geom type="mesh" rgba="1.0 1.0 1.0 1" mesh="right_ankle_pitch_link" />

                <body name="right_ankle_roll_link" pos="0.0 0.024 0.0">
                  <inertial pos="0.039477 -0.002886 -0.032098" quat="0.999151 -0.009249 0.020679 0.034410" mass="0.15"
        diaginertia="0.000127095 0.000547706 0.00063363" />
                  <joint name="right_ankle_roll_joint" pos="0 0 0" axis="1 0 0"
                    range="-0.2618 0.2618" actuatorfrcrange="-27 27" class="ankle_motor" />
                  <geom type="mesh" contype="0" conaffinity="0" group="1" density="0" rgba="1.0 1.0 1.0 1"
                    mesh="right_ankle_roll_link" />
                  <geom size="0.005" pos="-0.05 0.030 -0.046" rgba="1.0 1.0 1.0 1"/>
                  <geom size="0.005" pos="-0.05 -0.038 -0.046" rgba="1.0 1.0 1.0 1"/>
                  <geom size="0.005" pos="0.15 0.034 -0.046" rgba="1.0 1.0 1.0 1"/>
                  <geom size="0.005" pos="0.15 -0.020 -0.046" rgba="1.0 1.0 1.0 1"/>
                  <geom name="right_foot_collision" type="box" size="0.08 0.04 0.02" pos="0.05 0 -0.04" contype="0" conaffinity="0" rgba=".2 .2 .6 .2" group="3"/>
                </body>
              </body>
            </body>
          </body>
        </body>
      </body>

      <!-- Upper Body -->
      <body name="waist_yaw_link" pos="0.0 0.0 0.0">
        <inertial pos="0.000703 0.000036 0.023511" quat="0.707107 0.707106 -0.000660 0.000661" mass="0.79"
        diaginertia="0.000424112 0.00115195 0.00139043" />
        <joint name="waist_yaw_joint" pos="0 0 0" axis="0 0 1" range="-2.618 2.618"
          actuatorfrcrange="-97 97" class="torso_motor" />
        <geom type="mesh" contype="0" conaffinity="0" group="1" density="0" rgba="1.0 1.0 1.0 1"
          mesh="waist_yaw_link" />
        <geom type="mesh" rgba="1.0 1.0 1.0 1" mesh="waist_yaw_link" contype="2" conaffinity="1" />

        <body name="waist_roll_link" pos="0.03813 3.7e-05 0.050906">
          <inertial pos="-0.036458 0.001915 0.039503" quat="-0.497668 -0.522864 -0.452622 0.523520" mass="1.56"
        diaginertia="0.00121052 0.00366195 0.00366507" />
          <joint name="waist_roll_joint" pos="0 0 0" axis="1 0 0" range="-0.52 0.52"
            actuatorfrcrange="-97 97" class="torso_motor" />
          <geom type="mesh" contype="0" conaffinity="0" group="1" density="0" rgba="1.0 1.0 1.0 1"
            mesh="waist_roll_link" />
          <geom type="mesh" rgba="1.0 1.0 1.0 1" mesh="waist_roll_link" contype="2" conaffinity="1" />

          <body name="torso_link" pos="-0.03813 -0.032925 0.079963">
            <inertial pos="-0.000218 0.028412 0.216121" quat="-0.012746 0.707391 0.013049 -0.706587" mass="2.01"
        diaginertia="0.0103593 0.031659 0.0398056" />
            <joint name="waist_pitch_joint" pos="0 0 0" axis="0 1 0" range="-0.52 0.52"
              actuatorfrcrange="-97 97" class="torso_motor" />
            <geom type="mesh" contype="0" conaffinity="0" group="1" density="0" rgba="1.0 1.0 1.0 1"
              mesh="waist_pitch_link" />
            <geom type="mesh" rgba="1.0 1.0 1.0 1" mesh="waist_pitch_link" contype="2" conaffinity="1" />
            <geom name="torso_collision" type="box" size="0.12 0.15 0.15" pos="0 0.03 0.2" contype="0" conaffinity="0" rgba=".6 .2 .2 .2" group="3"/>

            <!-- Left Arm -->
            <body name="left_shoulder_pitch_link" pos="0.0 0.13582 0.33654"
              quat="0.9659258 0.2588190 0 0">
              <inertial pos="-0.003496 0.038568 0.000147" quat="0.942818 0.005189 0.001305 -0.333265" mass="0.24"
        diaginertia="0.000216626 0.000302215 0.000438512" />
              <joint name="left_shoulder_pitch_joint" pos="0 0 0" axis="0 1 0"
                range="-2.0 2.0" actuatorfrcrange="-27 27" class="arm_motor" />
              <geom type="mesh" contype="0" conaffinity="0" group="1" density="0" rgba="1.0 1.0 1.0 1"
                mesh="left_shoulder_pitch_link" />
              <geom type="mesh" rgba="1.0 1.0 1.0 1" mesh="left_shoulder_pitch_link" />

              <body name="left_shoulder_roll_link" pos="0.03476 0.0835 0.000425"
                quat="0.9659258 -0.2588190 0 0">
                <inertial pos="-0.034326 0.004104 -0.054527" quat="-0.466607 0.541513 0.529133 0.457232" mass="0.92"
        diaginertia="0.00160635 0.00174986 0.00232011" />
                <joint name="left_shoulder_roll_joint" pos="0 0 0" axis="1 0 0"
                  range="-0.2 2.2515" actuatorfrcrange="-27 27" class="arm_motor" />
                <geom type="mesh" contype="0" conaffinity="0" group="1" density="0" rgba="1.0 1.0 1.0 1"
                  mesh="left_shoulder_roll_link" />
                <geom type="mesh" rgba="1.0 1.0 1.0 1" mesh="left_shoulder_roll_link" />
                <geom name="left_upper_arm_collision" type="capsule" size="0.04" fromto="0 0 0 -0.03 0 -0.1" contype="0" conaffinity="0" rgba=".2 .6 .6 .2" group="3"/>

                <body name="left_shoulder_yaw_link" pos="-0.034375 0.0 -0.12">
                  <inertial pos="0.000352 -0.000067 -0.086391" quat="-0.705828 -0.040991 0.706119 -0.039023" mass="0.625"
        diaginertia="0.000836482 0.00204864 0.002069" />
                  <joint name="left_shoulder_yaw_joint" pos="0 0 0" axis="0 0 1"
                    range="-2.58 2.58" actuatorfrcrange="-27 27" class="arm_motor" />
                  <geom type="mesh" contype="0" conaffinity="0" group="1" density="0" rgba="1.0 1.0 1.0 1"
                    mesh="left_shoulder_yaw_link" />
                  <geom type="mesh" rgba="1.0 1.0 1.0 1" mesh="left_shoulder_yaw_link" contype="8" conaffinity="1" />

                  <body name="left_elbow_link" pos="0.000364 0.029113 -0.18099">
                    <inertial pos="0.060290 -0.018897 -0.005505" quat="0.997566 0.037813 -0.047139 -0.034794" mass="0.552"
        diaginertia="0.000980685 0.00143241 0.00168229" />
                    <joint name="left_elbow_joint" pos="0 0 0" axis="0 1 0"
                      range="-0.7 1.57" actuatorfrcrange="-27 27" class="arm_motor" />
                    <geom type="mesh" contype="0" conaffinity="0" group="1" density="0" rgba="1.0 1.0 1.0 1"
                      mesh="left_elbow_link" />
                    <geom type="mesh" rgba="1.0 1.0 1.0 1" mesh="left_elbow_link" contype="8" conaffinity="1" />
                    <geom name="left_forearm_collision" type="capsule" size="0.035" fromto="0.02 0 0 0.12 -0.02 0" contype="0" conaffinity="0" rgba=".2 .6 .6 .2" group="3"/>

                    <body name="left_wrist_roll_link" pos="0.13 -0.029125 0.0">
                      <inertial pos="0.059365 -0.000127 0.000856" quat="0.709390 0.704504 -0.014627 0.015066" mass="0.508"
        diaginertia="0.000846714 0.00108933 0.00119508" />
                      <joint name="left_wrist_roll_joint" pos="0 0 0" axis="1 0 0"
                        range="-2.67 2.67" actuatorfrcrange="-7 7" class="wrist_motor" />
                      <geom type="mesh" contype="0" conaffinity="0" group="1" density="0" rgba="1.0 1.0 1.0 1"
                        mesh="left_wrist_roll_link" />
                      <geom type="mesh" rgba="1.0 1.0 1.0 1" mesh="left_wrist_roll_link" contype="8" conaffinity="1" />

                      <body name="left_wrist_yaw_link" pos="0.121 0.0 -0.0333">
                        <inertial pos="0.000001 0.001808 0.034229" quat="0.505557 -0.497530 -0.494299 -0.502538" mass="0.37"
        diaginertia="0.00015129 0.000161838 0.000185039" />
                        <joint name="left_wrist_yaw_joint" pos="0 0 0" axis="0 0 1"
                          range="-0.9 0.9" actuatorfrcrange="-7 7" class="wrist_motor" />
                        <geom type="mesh" contype="0" conaffinity="0" group="1" density="0" rgba="1.0 1.0 1.0 1"
                          mesh="left_wrist_yaw_link" />
                        <geom type="mesh" rgba="1.0 1.0 1.0 1" mesh="left_wrist_yaw_link" contype="8" conaffinity="1" />

                        <body name="left_wrist_pitch_link" pos="0.0 0.0225 0.0333">
                          <inertial pos="0.104643 -0.016206 0.000018" quat="0.980713 0.000558 -0.001037 -0.195452" mass="0.308"
        diaginertia="0.000366887 0.000729769 0.00103831"/>
                          <joint name="left_wrist_pitch_joint" pos="0 0 0" axis="0 1 0"
                            range="-0.9 0.9" actuatorfrcrange="-7 7" class="wrist_motor" />
                          <geom type="mesh" contype="0" conaffinity="0" group="1" density="0" rgba="1.0 1.0 1.0 1"
                            mesh="left_wrist_pitch_link" />
                          <geom type="mesh" rgba="1.0 1.0 1.0 1" mesh="left_wrist_pitch_link" contype="8" conaffinity="1" />
                          <geom name="left_hand_collision" type="sphere" size="0.1" pos="0.12 -0.02 0" contype="0" conaffinity="0" rgba=".2 .6 .2 .2" group="3"/>
                        </body>
                      </body>
                    </body>
                  </body>
                </body>
              </body>
            </body>

            <!-- Right Arm -->
            <body name="right_shoulder_pitch_link" pos="0.0 -0.069974 0.33654"
              quat="0.9659258 -0.2588190 0 0">
              <inertial pos="-0.003496 -0.038568 0.000147" quat="0.942818 -0.005194 0.001309 0.333265" mass="0.24"
        diaginertia="0.000216626 0.000302215 0.000438512" />
              <joint name="right_shoulder_pitch_joint" pos="0 0 0" axis="0 1 0"
                range="-2.0 2.0" actuatorfrcrange="-27 27" class="arm_motor" />
              <geom type="mesh" contype="0" conaffinity="0" group="1" density="0" rgba="1.0 1.0 1.0 1"
                mesh="right_shoulder_pitch_link" />
              <geom type="mesh" rgba="1.0 1.0 1.0 1" mesh="right_shoulder_pitch_link" />

              <body name="right_shoulder_roll_link" pos="0.02776 -0.0835 0.000425"
                quat="0.9659258 0.2588190 0 0">
                <inertial pos="-0.027387 -0.004099 -0.054543" quat="0.538692 -0.464976 -0.459110 -0.531814" mass="0.92"
        diaginertia="0.00160664 0.00174971 0.00232021" />
                <joint name="right_shoulder_roll_joint" pos="0 0 0" axis="1 0 0"
                  range="-2.2515 0.2" actuatorfrcrange="-27 27" class="arm_motor" />
                <geom type="mesh" contype="0" conaffinity="0" group="1" density="0" rgba="1.0 1.0 1.0 1"
                  mesh="right_shoulder_roll_link" />
                <geom type="mesh" rgba="1.0 1.0 1.0 1" mesh="right_shoulder_roll_link" />
                <geom name="right_upper_arm_collision" type="capsule" size="0.04" fromto="0 0 0 -0.03 0 -0.1" contype="0" conaffinity="0" rgba=".2 .6 .6 .2" group="3"/>

                <body name="right_shoulder_yaw_link" pos="-0.027375 0.0 -0.12">
                  <inertial pos="0.000351 0.000061 -0.086330" quat="0.706146 0.036788 -0.706063 0.038462" mass="0.625"
        diaginertia="0.000836592 0.00204945 0.00206961" />
                  <joint name="right_shoulder_yaw_joint" pos="0 0 0" axis="0 0 1"
                    range="-2.58 2.58" actuatorfrcrange="-27 27" class="arm_motor" />
                  <geom type="mesh" contype="0" conaffinity="0" group="1" density="0" rgba="1.0 1.0 1.0 1"
                    mesh="right_shoulder_yaw_link" />
                  <geom type="mesh" rgba="1.0 1.0 1.0 1" mesh="right_shoulder_yaw_link" contype="16" conaffinity="1" />

                  <body name="right_elbow_link" pos="0.000364 0.027375 -0.18099">
                    <inertial pos="0.060609 -0.027320 -0.005391" quat="0.998910 0.001174 -0.046413 0.004845" mass="0.552"
        diaginertia="0.00103959 0.00142282 0.00173271" />
                    <joint name="right_elbow_joint" pos="0 0 0" axis="0 1 0"
                      range="-0.7 1.57" actuatorfrcrange="-27 27" class="arm_motor" />
                    <geom type="mesh" contype="0" conaffinity="0" group="1" density="0" rgba="1.0 1.0 1.0 1"
                      mesh="right_elbow_link" />
                    <geom type="mesh" rgba="1.0 1.0 1.0 1" mesh="right_elbow_link" contype="16" conaffinity="1" />
                    <geom name="right_forearm_collision" type="capsule" size="0.035" fromto="0.02 0 0 0.12 -0.02 0" contype="0" conaffinity="0" rgba=".2 .6 .6 .2" group="3"/>

                    <body name="right_wrist_roll_link" pos="0.13 -0.027375 0.0">
                      <inertial pos="0.059348 -0.000124 0.000828" quat="0.709304 0.704564 -0.015028 0.015864" mass="0.508"
        diaginertia="0.000846771 0.00108988 0.00119553" />
                      <joint name="right_wrist_roll_joint" pos="0 0 0" axis="1 0 0"
                        range="-2.67 2.67" actuatorfrcrange="-7 7" class="wrist_motor" />
                      <geom type="mesh" contype="0" conaffinity="0" group="1" density="0" rgba="1.0 1.0 1.0 1"
                        mesh="right_wrist_roll_link" />
                      <geom type="mesh" rgba="1.0 1.0 1.0 1" mesh="right_wrist_roll_link" contype="16" conaffinity="1" />

                      <body name="right_wrist_yaw_link" pos="0.121 0.0 -0.0333">
                        <inertial pos="-0.000001 -0.001805 0.034231" quat="-0.502813 -0.494486 -0.497307 0.505320" mass="0.37"
        diaginertia="0.000151278 0.00016184 0.000185025" />
                        <joint name="right_wrist_yaw_joint" pos="0 0 0" axis="0 0 1"
                          range="-0.9 0.9" actuatorfrcrange="-7 7" class="wrist_motor" />
                        <geom type="mesh" contype="0" conaffinity="0" group="1" density="0" rgba="1.0 1.0 1.0 1"
                          mesh="right_wrist_yaw_link" />
                        <geom type="mesh" rgba="1.0 1.0 1.0 1" mesh="right_wrist_yaw_link" contype="16" conaffinity="1" />

                        <body name="right_wrist_pitch_link" pos="0.0 -0.0225 0.0333">
                          <inertial pos="0.104643 0.016206 0.000018" quat="0.980713 -0.000558 -0.001037 0.195450" mass="0.308"
        diaginertia="0.000366888 0.000729776 0.00103832"/>
                          <joint name="right_wrist_pitch_joint" pos="0 0 0" axis="0 1 0"
                            range="-0.9 0.9" actuatorfrcrange="-7 7" class="wrist_motor" />
                          <geom type="mesh" contype="0" conaffinity="0" group="1" density="0" rgba="1.0 1.0 1.0 1"
                            mesh="right_wrist_pitch_link" />
                          <geom type="mesh" rgba="1.0 1.0 1.0 1" mesh="right_wrist_pitch_link" contype="16" conaffinity="1" />
                          <geom name="right_hand_collision" type="sphere" size="0.1" pos="0.12 0.02 0" contype="0" conaffinity="0" rgba=".2 .6 .2 .2" group="3"/>
                        </body>
                      </body>
                    </body>
                  </body>
                </body>
              </body>
            </body>

            <!-- Neck -->
            <body name="neck_yaw_link" pos="0.0 0.032906 0.37165" quat="1 3.2e-05 0 0">
              <inertial pos="-0.026017 0.000004 0.044450" quat="-0.000003 0.399078 0.000064 0.916917" mass="0.4"
        diaginertia="0.000158273 0.000510001 0.000543254" />
              <joint name="neck_yaw_joint" pos="0 0 0" axis="0 0 1" range="-1.57 1.57"
                actuatorfrcrange="-3 3" class="neck_motor" />
              <geom type="mesh" contype="0" conaffinity="0" group="1" density="0" rgba="1.0 1.0 1.0 1"
                mesh="neck_yaw_link" />
              <geom type="mesh" rgba="1.0 1.0 1.0 1" mesh="neck_yaw_link" contype="4" conaffinity="1" />

              <body name="neck_roll_link" pos="-0.0719 0.0 0.0708">
                <inertial pos="0.057357 -0.000598 -0.000025" quat="-0.674875 -0.000416 0.000618 0.737931" mass="0.026"
        diaginertia="6.4839e-06 1.35416e-05 1.62635e-05" />
                <joint name="neck_roll_joint" pos="0 0 0" axis="1 0 0" range="-0.873 0.873"
                  actuatorfrcrange="-3 3" class="neck_motor" />
                <geom type="mesh" contype="0" conaffinity="0" group="1" density="0" rgba="1.0 1.0 1.0 1"
                  mesh="neck_roll_link" />
                <geom type="mesh" rgba="1.0 1.0 1.0 1" mesh="neck_roll_link" contype="4" conaffinity="1" />

                <body name="neck_pitch_link" pos="0.0719 0.02095 0.0">
                  <inertial pos="0.009305 -0.020598 0.085322" quat="0.551128 0.557629 0.439744 -0.438101" mass="0.6"
        diaginertia="0.00224315 0.00340582 0.00427196" />
                  <joint name="neck_pitch_joint" pos="0 0 0" axis="0 1 0" range="-0.873 0.873"
                    actuatorfrcrange="-3 3" class="neck_motor" />
                  <geom type="mesh" contype="0" conaffinity="0" group="1" density="0" rgba="1.0 1.0 1.0 1"
                    mesh="neck_pitch_link" />
                  <geom type="mesh" rgba="1.0 1.0 1.0 1" mesh="neck_pitch_link" contype="4" conaffinity="1" />
                  <geom name="head_collision" type="sphere" size="0.12" pos="0.0 -0.02 0.1" contype="0" conaffinity="0" rgba=".8 .6 .2 .2" group="3"/>
                </body>
              </body>
            </body>
          </body>
        </body>
      </body>
    </body>
  </worldbody>

  <!-- Actuators按训练顺序排列 (32 DOF) - 与IO descriptor一致 -->
  <actuator>
    <!-- 0: left_hip_pitch_joint -->
    <motor name="left_hip_pitch" joint="left_hip_pitch_joint" ctrlrange="-120 120" />
    <!-- 1: right_hip_pitch_joint -->
    <motor name="right_hip_pitch" joint="right_hip_pitch_joint" ctrlrange="-120 120" />
    <!-- 2: waist_yaw_joint -->
    <motor name="waist_yaw" joint="waist_yaw_joint" ctrlrange="-97 97" />
    <!-- 3: left_hip_roll_joint -->
    <motor name="left_hip_roll" joint="left_hip_roll_joint" ctrlrange="-97 97" />
    <!-- 4: right_hip_roll_joint -->
    <motor name="right_hip_roll" joint="right_hip_roll_joint" ctrlrange="-97 97" />
    <!-- 5: waist_roll_joint -->
    <motor name="waist_roll" joint="waist_roll_joint" ctrlrange="-97 97" />
    <!-- 6: left_hip_yaw_joint -->
    <motor name="left_hip_yaw" joint="left_hip_yaw_joint" ctrlrange="-97 97" />
    <!-- 7: right_hip_yaw_joint -->
    <motor name="right_hip_yaw" joint="right_hip_yaw_joint" ctrlrange="-97 97" />
    <!-- 8: waist_pitch_joint -->
    <motor name="waist_pitch" joint="waist_pitch_joint" ctrlrange="-97 97" />
    <!-- 9: left_knee_joint -->
    <motor name="left_knee" joint="left_knee_joint" ctrlrange="-120 120" />
    <!-- 10: right_knee_joint -->
    <motor name="right_knee" joint="right_knee_joint" ctrlrange="-120 120" />
    <!-- 11: left_shoulder_pitch_joint -->
    <motor name="left_shoulder_pitch" joint="left_shoulder_pitch_joint" ctrlrange="-27 27" />
    <!-- 12: neck_yaw_joint -->
    <motor name="neck_yaw" joint="neck_yaw_joint" ctrlrange="-3 3" />
    <!-- 13: right_shoulder_pitch_joint -->
    <motor name="right_shoulder_pitch" joint="right_shoulder_pitch_joint" ctrlrange="-27 27" />
    <!-- 14: left_ankle_pitch_joint -->
    <motor name="left_ankle_pitch" joint="left_ankle_pitch_joint" ctrlrange="-27 27" />
    <!-- 15: right_ankle_pitch_joint -->
    <motor name="right_ankle_pitch" joint="right_ankle_pitch_joint" ctrlrange="-27 27" />
    <!-- 16: left_shoulder_roll_joint -->
    <motor name="left_shoulder_roll" joint="left_shoulder_roll_joint" ctrlrange="-27 27" />
    <!-- 17: neck_roll_joint -->
    <motor name="neck_roll" joint="neck_roll_joint" ctrlrange="-3 3" />
    <!-- 18: right_shoulder_roll_joint -->
    <motor name="right_shoulder_roll" joint="right_shoulder_roll_joint" ctrlrange="-27 27" />
    <!-- 19: left_ankle_roll_joint -->
    <motor name="left_ankle_roll" joint="left_ankle_roll_joint" ctrlrange="-27 27" />
    <!-- 20: right_ankle_roll_joint -->
    <motor name="right_ankle_roll" joint="right_ankle_roll_joint" ctrlrange="-27 27" />
    <!-- 21: left_shoulder_yaw_joint -->
    <motor name="left_shoulder_yaw" joint="left_shoulder_yaw_joint" ctrlrange="-27 27" />
    <!-- 22: neck_pitch_joint -->
    <motor name="neck_pitch" joint="neck_pitch_joint" ctrlrange="-3 3" />
    <!-- 23: right_shoulder_yaw_joint -->
    <motor name="right_shoulder_yaw" joint="right_shoulder_yaw_joint" ctrlrange="-27 27" />
    <!-- 24: left_elbow_joint -->
    <motor name="left_elbow" joint="left_elbow_joint" ctrlrange="-27 27" />
    <!-- 25: right_elbow_joint -->
    <motor name="right_elbow" joint="right_elbow_joint" ctrlrange="-27 27" />
    <!-- 26: left_wrist_roll_joint -->
    <motor name="left_wrist_roll" joint="left_wrist_roll_joint" ctrlrange="-7 7" />
    <!-- 27: right_wrist_roll_joint -->
    <motor name="right_wrist_roll" joint="right_wrist_roll_joint" ctrlrange="-7 7" />
    <!-- 28: left_wrist_yaw_joint -->
    <motor name="left_wrist_yaw" joint="left_wrist_yaw_joint" ctrlrange="-7 7" />
    <!-- 29: right_wrist_yaw_joint -->
    <motor name="right_wrist_yaw" joint="right_wrist_yaw_joint" ctrlrange="-7 7" />
    <!-- 30: left_wrist_pitch_joint -->
    <motor name="left_wrist_pitch" joint="left_wrist_pitch_joint" ctrlrange="-7 7" />
    <!-- 31: right_wrist_pitch_joint -->
    <motor name="right_wrist_pitch" joint="right_wrist_pitch_joint" ctrlrange="-7 7" />
  </actuator>

  <!-- Sensors按训练顺序排列 (32 DOF) - 与actuator顺序一致 -->
  <sensor>
    <!-- Joint positions (0-31) -->
    <jointpos name="left_hip_pitch_pos" joint="left_hip_pitch_joint" />
    <jointpos name="right_hip_pitch_pos" joint="right_hip_pitch_joint" />
    <jointpos name="waist_yaw_pos" joint="waist_yaw_joint" />
    <jointpos name="left_hip_roll_pos" joint="left_hip_roll_joint" />
    <jointpos name="right_hip_roll_pos" joint="right_hip_roll_joint" />
    <jointpos name="waist_roll_pos" joint="waist_roll_joint" />
    <jointpos name="left_hip_yaw_pos" joint="left_hip_yaw_joint" />
    <jointpos name="right_hip_yaw_pos" joint="right_hip_yaw_joint" />
    <jointpos name="waist_pitch_pos" joint="waist_pitch_joint" />
    <jointpos name="left_knee_pos" joint="left_knee_joint" />
    <jointpos name="right_knee_pos" joint="right_knee_joint" />
    <jointpos name="left_shoulder_pitch_pos" joint="left_shoulder_pitch_joint" />
    <jointpos name="neck_yaw_pos" joint="neck_yaw_joint" />
    <jointpos name="right_shoulder_pitch_pos" joint="right_shoulder_pitch_joint" />
    <jointpos name="left_ankle_pitch_pos" joint="left_ankle_pitch_joint" />
    <jointpos name="right_ankle_pitch_pos" joint="right_ankle_pitch_joint" />
    <jointpos name="left_shoulder_roll_pos" joint="left_shoulder_roll_joint" />
    <jointpos name="neck_roll_pos" joint="neck_roll_joint" />
    <jointpos name="right_shoulder_roll_pos" joint="right_shoulder_roll_joint" />
    <jointpos name="left_ankle_roll_pos" joint="left_ankle_roll_joint" />
    <jointpos name="right_ankle_roll_pos" joint="right_ankle_roll_joint" />
    <jointpos name="left_shoulder_yaw_pos" joint="left_shoulder_yaw_joint" />
    <jointpos name="neck_pitch_pos" joint="neck_pitch_joint" />
    <jointpos name="right_shoulder_yaw_pos" joint="right_shoulder_yaw_joint" />
    <jointpos name="left_elbow_pos" joint="left_elbow_joint" />
    <jointpos name="right_elbow_pos" joint="right_elbow_joint" />
    <jointpos name="left_wrist_roll_pos" joint="left_wrist_roll_joint" />
    <jointpos name="right_wrist_roll_pos" joint="right_wrist_roll_joint" />
    <jointpos name="left_wrist_yaw_pos" joint="left_wrist_yaw_joint" />
    <jointpos name="right_wrist_yaw_pos" joint="right_wrist_yaw_joint" />
    <jointpos name="left_wrist_pitch_pos" joint="left_wrist_pitch_joint" />
    <jointpos name="right_wrist_pitch_pos" joint="right_wrist_pitch_joint" />

    <!-- Joint velocities (32-63) -->
    <jointvel name="left_hip_pitch_vel" joint="left_hip_pitch_joint" />
    <jointvel name="right_hip_pitch_vel" joint="right_hip_pitch_joint" />
    <jointvel name="waist_yaw_vel" joint="waist_yaw_joint" />
    <jointvel name="left_hip_roll_vel" joint="left_hip_roll_joint" />
    <jointvel name="right_hip_roll_vel" joint="right_hip_roll_joint" />
    <jointvel name="waist_roll_vel" joint="waist_roll_joint" />
    <jointvel name="left_hip_yaw_vel" joint="left_hip_yaw_joint" />
    <jointvel name="right_hip_yaw_vel" joint="right_hip_yaw_joint" />
    <jointvel name="waist_pitch_vel" joint="waist_pitch_joint" />
    <jointvel name="left_knee_vel" joint="left_knee_joint" />
    <jointvel name="right_knee_vel" joint="right_knee_joint" />
    <jointvel name="left_shoulder_pitch_vel" joint="left_shoulder_pitch_joint" />
    <jointvel name="neck_yaw_vel" joint="neck_yaw_joint" />
    <jointvel name="right_shoulder_pitch_vel" joint="right_shoulder_pitch_joint" />
    <jointvel name="left_ankle_pitch_vel" joint="left_ankle_pitch_joint" />
    <jointvel name="right_ankle_pitch_vel" joint="right_ankle_pitch_joint" />
    <jointvel name="left_shoulder_roll_vel" joint="left_shoulder_roll_joint" />
    <jointvel name="neck_roll_vel" joint="neck_roll_joint" />
    <jointvel name="right_shoulder_roll_vel" joint="right_shoulder_roll_joint" />
    <jointvel name="left_ankle_roll_vel" joint="left_ankle_roll_joint" />
    <jointvel name="right_ankle_roll_vel" joint="right_ankle_roll_joint" />
    <jointvel name="left_shoulder_yaw_vel" joint="left_shoulder_yaw_joint" />
    <jointvel name="neck_pitch_vel" joint="neck_pitch_joint" />
    <jointvel name="right_shoulder_yaw_vel" joint="right_shoulder_yaw_joint" />
    <jointvel name="left_elbow_vel" joint="left_elbow_joint" />
    <jointvel name="right_elbow_vel" joint="right_elbow_joint" />
    <jointvel name="left_wrist_roll_vel" joint="left_wrist_roll_joint" />
    <jointvel name="right_wrist_roll_vel" joint="right_wrist_roll_joint" />
    <jointvel name="left_wrist_yaw_vel" joint="left_wrist_yaw_joint" />
    <jointvel name="right_wrist_yaw_vel" joint="right_wrist_yaw_joint" />
    <jointvel name="left_wrist_pitch_vel" joint="left_wrist_pitch_joint" />
    <jointvel name="right_wrist_pitch_vel" joint="right_wrist_pitch_joint" />

    <!-- Joint actuator forces (64-95) -->
    <jointactuatorfrc name="left_hip_pitch_torque" joint="left_hip_pitch_joint" />
    <jointactuatorfrc name="right_hip_pitch_torque" joint="right_hip_pitch_joint" />
    <jointactuatorfrc name="waist_yaw_torque" joint="waist_yaw_joint" />
    <jointactuatorfrc name="left_hip_roll_torque" joint="left_hip_roll_joint" />
    <jointactuatorfrc name="right_hip_roll_torque" joint="right_hip_roll_joint" />
    <jointactuatorfrc name="waist_roll_torque" joint="waist_roll_joint" />
    <jointactuatorfrc name="left_hip_yaw_torque" joint="left_hip_yaw_joint" />
    <jointactuatorfrc name="right_hip_yaw_torque" joint="right_hip_yaw_joint" />
    <jointactuatorfrc name="waist_pitch_torque" joint="waist_pitch_joint" />
    <jointactuatorfrc name="left_knee_torque" joint="left_knee_joint" />
    <jointactuatorfrc name="right_knee_torque" joint="right_knee_joint" />
    <jointactuatorfrc name="left_shoulder_pitch_torque" joint="left_shoulder_pitch_joint" />
    <jointactuatorfrc name="neck_yaw_torque" joint="neck_yaw_joint" />
    <jointactuatorfrc name="right_shoulder_pitch_torque" joint="right_shoulder_pitch_joint" />
    <jointactuatorfrc name="left_ankle_pitch_torque" joint="left_ankle_pitch_joint" />
    <jointactuatorfrc name="right_ankle_pitch_torque" joint="right_ankle_pitch_joint" />
    <jointactuatorfrc name="left_shoulder_roll_torque" joint="left_shoulder_roll_joint" />
    <jointactuatorfrc name="neck_roll_torque" joint="neck_roll_joint" />
    <jointactuatorfrc name="right_shoulder_roll_torque" joint="right_shoulder_roll_joint" />
    <jointactuatorfrc name="left_ankle_roll_torque" joint="left_ankle_roll_joint" />
    <jointactuatorfrc name="right_ankle_roll_torque" joint="right_ankle_roll_joint" />
    <jointactuatorfrc name="left_shoulder_yaw_torque" joint="left_shoulder_yaw_joint" />
    <jointactuatorfrc name="neck_pitch_torque" joint="neck_pitch_joint" />
    <jointactuatorfrc name="right_shoulder_yaw_torque" joint="right_shoulder_yaw_joint" />
    <jointactuatorfrc name="left_elbow_torque" joint="left_elbow_joint" />
    <jointactuatorfrc name="right_elbow_torque" joint="right_elbow_joint" />
    <jointactuatorfrc name="left_wrist_roll_torque" joint="left_wrist_roll_joint" />
    <jointactuatorfrc name="right_wrist_roll_torque" joint="right_wrist_roll_joint" />
    <jointactuatorfrc name="left_wrist_yaw_torque" joint="left_wrist_yaw_joint" />
    <jointactuatorfrc name="right_wrist_yaw_torque" joint="right_wrist_yaw_joint" />
    <jointactuatorfrc name="left_wrist_pitch_torque" joint="left_wrist_pitch_joint" />
    <jointactuatorfrc name="right_wrist_pitch_torque" joint="right_wrist_pitch_joint" />

    <!-- IMU sensors -->
    <framequat name="imu_quat" objtype="site" objname="imu" />
    <gyro name="imu_gyro" site="imu" />
    <accelerometer name="imu_acc" site="imu" />

    <framepos name="frame_pos" objtype="site" objname="imu" />
    <framelinvel name="frame_vel" objtype="site" objname="imu" />
  </sensor>

</mujoco>
